Workbook

Sheet Лист4
B2: Сводная таблица в разрезе недель и территорий
A5: Сумма по полю Товарооборот, руб | B5: Неделя
A6: Территория | B6: 18 | C6: 19 | D6: 20 | E6: 21 | F6: 22 | G6: 23 | H6: Общий итог
A7: Волгоград | B7: 36934095 | C7: 43307156 | D7: 41300679 | E7: 44172813 | F7: 46485094 | G7: 5800290 | H7: 218000127
A8: Екатеринбург | B8: 42828758 | C8: 46366010 | D8: 47079842 | E8: 49575288 | F8: 50729186 | G8: 6829921.5 | H8: 2.43409e+08
A9: Казань | B9: 17828216 | C9: 20974521 | D9: 23603355 | E9: 26815804 | F9: 27495690 | G9: 3865251 | H9: 120582837
A10: Кемерово | B10: 16029680 | C10: 19479056 | D10: 19724733 | E10: 20915751 | F10: 22579281 | G10: 2945035.5 | H10: 1.0167354e+08
A11: Краснодар | B11: 13955985 | C11: 16391856 | D11: 16732521 | E11: 17647479 | F11: 18595773 | G11: 2538967.5 | H11: 85862582
A12: Москва Восток | B12: 130713645 | C12: 1.5164204e+08 | D12: 135813990 | E12: 149589546 | F12: 151451013 | G12: 18914194 | H12: 738124428
A13: Москва Запад | B13: 136791225 | C13: 159695760 | D13: 142825023 | E13: 1.5751236e+08 | F13: 1.5785721e+08 | G13: 19465372 | H13: 7.7414695e+08
A14: Нижний Новгород | B14: 13145966 | C14: 17149980 | D14: 19963154 | E14: 20713983 | F14: 21605704 | G14: 3013512 | H14: 95592298
A15: Новосибирск | B15: 5746024.5 | C15: 7253572.5 | D15: 7841920.5 | E15: 8990269.5 | F15: 9909624 | G15: 1293219 | H15: 41034630
A16: Пермь | B16: 6961020 | C16: 8778597 | D16: 9036316.5 | E16: 10598445 | F16: 11902053 | G16: 1526608.5 | H16: 48803040
A17: Ростов-на-Дону | B17: 2008809 | C17: 5892277.5 | D17: 7382458.5 | E17: 8638525.5 | F17: 9328845 | G17: 1565632.5 | H17: 34816548
A18: Самара | F18: 2706253.5 | G18: 636345 | H18: 3342598.5
A19: Санкт-Петербург Север | B19: 233059077 | C19: 2.727625e+08 | D19: 269949999 | E19: 2.7553943e+08 | F19: 2.9215505e+08 | G19: 37257840 | H19: 1.3807239e+09
A20: Санкт-Петербург Юг | B20: 176269533 | C20: 2.0812839e+08 | D20: 1.9956962e+08 | E20: 2.0460881e+08 | F20: 2.1926593e+08 | G20: 27770092 | H20: 1.0356124e+09
A21: Тольятти | B21: 4531000.5 | C21: 6093688.5 | D21: 6439392 | E21: 7373379 | F21: 7762362 | G21: 1007742 | H21: 33207564
A22: Томск | F22: 493893 | G22: 389013 | H22: 882906
A23: Тюмень | F23: 4861708.5 | G23: 802447.5 | H23: 5664156
A24: Уфа | F24: 468835.5 | G24: 410892 | H24: 879727.5
A25: Общий итог | B25: 836803032 | C25: 9.8391541e+08 | D25: 9.4726301e+08 | E25: 1.0026919e+09 | F25: 1.0556535e+09 | G25: 1.3603238e+08 | H25: 4.9623592e+09
A30: Доля в общем обороте | E30: Территории по товарообороту на склад за последнюю неделю
A32: Территория | B32: Сумма по полю Товарооборот, руб2 | C32: Сумма по полю Товарооборот, руб | E32: Сумма по полю Товарооборот на склад | F32: Неделя
A33: Санкт-Петербург Север | B33: 0.27823941 | C33: 1.3807239e+09 | E33: Территория | F33: 23 | G33: Общий итог
A34: Санкт-Петербург Юг | B34: 0.20869355 | C34: 1.0356124e+09 | E34: Москва Восток | F34: 350262.86 | G34: 350262.86
A35: Москва Запад | B35: 0.15600381 | C35: 7.7414695e+08 | E35: Москва Запад | F35: 329921.57 | G35: 329921.57
A36: Москва Восток | B36: 0.14874466 | C36: 738124428 | E36: Санкт-Петербург Север | F36: 302909.27 | G36: 302909.27
A37: Екатеринбург | B37: 0.049051065 | C37: 2.43409e+08 | E37: Екатеринбург | F37: 220320.05 | G37: 220320.05
A38: Волгоград | B38: 0.043930743 | C38: 218000127 | E38: Санкт-Петербург Юг | F38: 216953.85 | G38: 216953.85
A39: Казань | B39: 0.024299498 | C39: 120582837 | E39: Казань | F39: 168054.39 | G39: 168054.39
A40: Кемерово | B40: 0.020488951 | C40: 1.0167354e+08 | E40: Волгоград | F40: 156764.59 | G40: 156764.59
A41: Нижний Новгород | B41: 0.019263478 | C41: 95592298 | E41: Нижний Новгород | F41: 150675.6 | G41: 150675.6
A42: Краснодар | B42: 0.017302774 | C42: 85862582 | E42: Кемерово | F42: 140239.79 | G42: 140239.79
A43: Пермь | B43: 0.0098346447 | C43: 48803040 | E43: Краснодар | F43: 120903.21 | G43: 120903.21
A44: Новосибирск | B44: 0.0082691777 | C44: 41034630 | E44: Тюмень | F44: 114635.36 | G44: 114635.36
A45: Ростов-на-Дону | B45: 0.0070161281 | C45: 34816548 | E45: Тольятти | F45: 100774.2 | G45: 100774.2
... A51: Общий итог | B51: 1 | C51: 4.9623592e+09 | E51: Самара | F51: 42423 | G51: 42423
E52: Общий итог | F52: 2786041.4 | G52: 2786041.4
B77: Территория | C77: Товарооборот, руб | D77: Товарооборот на склад
...

Sheet Лист1
A1: Дата | B1: Территория | C1: Товарооборот, шт | D1: Товарооборот, руб | E1: Количество складов | F1: Количество заказов | G1: Количество клиентов | H1: Товарооборот на склад | I1: Неделя
A2: 43982 | B2: Самара | C2: 7944 | D2: 623971.5 | E2: =SUMIFS(Лист2!$C:$C,Лист2!$A:$A,A2,Лист2!$B:$B,B2) -> 15 | F2: =SUMIFS(Лист2!$D:$D,Лист2!$A:$A,A2,Лист2!$B:$B,B2) -> 441 | G2: =SUMIFS(Лист2!$E:$E,Лист2!$A:$A,A2,Лист2!$B:$B,B2) -> 368 | H2: =D2/E2 -> 41598.1 | I2: =WEEKNUM(A2,2) -> 22 | M2: Неделя | N2: Сумма по полю Товарооборот, руб | O2: Сумма по полю Количество складов
A3: 43981 | B3: Самара | C3: 10029 | D3: 787101 | E3: =SUMIFS(Лист2!$C:$C,Лист2!$A:$A,A3,Лист2!$B:$B,B3) -> 15 | F3: =SUMIFS(Лист2!$D:$D,Лист2!$A:$A,A3,Лист2!$B:$B,B3) -> 490 | G3: =SUMIFS(Лист2!$E:$E,Лист2!$A:$A,A3,Лист2!$B:$B,B3) -> 409 | H3: =D3/E3 -> 52473.4 | I3: =WEEKNUM(A3,2) -> 22 | M3: 18 | N3: 836803032 | O3: 3354
A4: 43979 | B4: Самара | C4: 8536.5 | D4: 643944 | E4: =SUMIFS(Лист2!$C:$C,Лист2!$A:$A,A4,Лист2!$B:$B,B4) -> 15 | F4: =SUMIFS(Лист2!$D:$D,Лист2!$A:$A,A4,Лист2!$B:$B,B4) -> 464 | G4: =SUMIFS(Лист2!$E:$E,Лист2!$A:$A,A4,Лист2!$B:$B,B4) -> 390 | H4: =D4/E4 -> 42929.6 | I4: =WEEKNUM(A4,2) -> 22 | M4: 19 | N4: 9.8391541e+08 | O4: 3977
A5: 43967 | B5: Кемерово | C5: 38947.5 | D5: 3395892 | E5: =SUMIFS(Лист2!$C:$C,Лист2!$A:$A,A5,Лист2!$B:$B,B5) -> 21 | F5: =SUMIFS(Лист2!$D:$D,Лист2!$A:$A,A5,Лист2!$B:$B,B5) -> 2145 | G5: =SUMIFS(Лист2!$E:$E,Лист2!$A:$A,A5,Лист2!$B:$B,B5) -> 1947 | H5: =D5/E5 -> 161709.14 | I5: =WEEKNUM(A5,2) -> 20 | M5: 20 | N5: 9.4726301e+08 | O5: 3994
A6: 43970 | B6: Кемерово | C6: 31842 | D6: 2771116.5 | E6: =SUMIFS(Лист2!$C:$C,Лист2!$A:$A,A6,Лист2!$B:$B,B6) -> 21 | F6: =SUMIFS(Лист2!$D:$D,Лист2!$A:$A,A6,Лист2!$B:$B,B6) -> 1860 | G6: =SUMIFS(Лист2!$E:$E,Лист2!$A:$A,A6,Лист2!$B:$B,B6) -> 1704 | H6: =D6/E6 -> 131957.93 | I6: =WEEKNUM(A6,2) -> 21 | M6: 21 | N6: 1.0026919e+09 | O6: 4020
A7: 43968 | B7: Кемерово | C7: 32023.5 | D7: 2882458.5 | E7: =SUMIFS(Лист2!$C:$C,Лист2!$A:$A,A7,Лист2!$B:$B,B7) -> 21 | F7: =SUMIFS(Лист2!$D:$D,Лист2!$A:$A,A7,Лист2!$B:$B,B7) -> 1874 | G7: =SUMIFS(Лист2!$E:$E,Лист2!$A:$A,A7,Лист2!$B:$B,B7) -> 1705 | H7: =D7/E7 -> 137259.93 | I7: =WEEKNUM(A7,2) -> 20 | M7: 22 | N7: 1.0556535e+09 | O7: 4151
A8: 43960 | B8: Кемерово | C8: 31147.5 | D8: 2831019 | E8: =SUMIFS(Лист2!$C:$C,Лист2!$A:$A,A8,Лист2!$B:$B,B8) -> 21 | F8: =SUMIFS(Лист2!$D:$D,Лист2!$A:$A,A8,Лист2!$B:$B,B8) -> 1735 | G8: =SUMIFS(Лист2!$E:$E,Лист2!$A:$A,A8,Лист2!$B:$B,B8) -> 1568 | H8: =D8/E8 -> 134810.43 | I8: =WEEKNUM(A8,2) -> 19 | M8: 23 | N8: 1.3603238e+08 | O8: 615
A9: 43955 | B9: Кемерово | C9: 25566 | D9: 2372310 | E9: =SUMIFS(Лист2!$C:$C,Лист2!$A:$A,A9,Лист2!$B:$B,B9) -> 20 | F9: =SUMIFS(Лист2!$D:$D,Лист2!$A:$A,A9,Лист2!$B:$B,B9) -> 1519 | G9: =SUMIFS(Лист2!$E:$E,Лист2!$A:$A,A9,Лист2!$B:$B,B9) -> 1372 | H9: =D9/E9 -> 118615.5 | I9: =WEEKNUM(A9,2) -> 19 | M9: Общий итог | N9: 4.9623592e+09 | O9: 20111
A10: 43950 | B10: Кемерово | C10: 29319 | D10: 2623480.5 | E10: =SUMIFS(Лист2!$C:$C,Лист2!$A:$A,A10,Лист2!$B:$B,B10) -> 18 | F10: =SUMIFS(Лист2!$D:$D,Лист2!$A:$A,A10,Лист2!$B:$B,B10) -> 1684 | G10: =SUMIFS(Лист2!$E:$E,Лист2!$A:$A,A10,Лист2!$B:$B,B10) -> 1528 | H10: =D10/E10 -> 145748.92 | I10: =WEEKNUM(A10,2) -> 18
A11: 43953 | B11: Кемерово | C11: 29031 | D11: 2711247 | E11: =SUMIFS(Лист2!$C:$C,Лист2!$A:$A,A11,Лист2!$B:$B,B11) -> 18 | F11: =SUMIFS(Лист2!$D:$D,Лист2!$A:$A,A11,Лист2!$B:$B,B11) -> 1708 | G11: =SUMIFS(Лист2!$E:$E,Лист2!$A:$A,A11,Лист2!$B:$B,B11) -> 1534 | H11: =D11/E11 -> 150624.83 | I11: =WEEKNUM(A11,2) -> 18
A12: 43977 | B12: Кемерово | C12: 33423 | D12: 2970330 | E12: =SUMIFS(Лист2!$C:$C,Лист2!$A:$A,A12,Лист2!$B:$B,B12) -> 20 | F12: =SUMIFS(Лист2!$D:$D,Лист2!$A:$A,A12,Лист2!$B:$B,B12) -> 2044 | G12: =SUMIFS(Лист2!$E:$E,Лист2!$A:$A,A12,Лист2!$B:$B,B12) -> 1863 | H12: =D12/E12 -> 148516.5 | I12: =WEEKNUM(A12,2) -> 22
A13: 43952 | B13: Кемерово | C13: 32487 | D13: 3031254 | E13: =SUMIFS(Лист2!$C:$C,Лист2!$A:$A,A13,Лист2!$B:$B,B13) -> 18 | F13: =SUMIFS(Лист2!$D:$D,Лист2!$A:$A,A13,Лист2!$B:$B,B13) -> 1826 | G13: =SUMIFS(Лист2!$E:$E,Лист2!$A:$A,A13,Лист2!$B:$B,B13) -> 1633 | H13: =D13/E13 -> 168403 | I13: =WEEKNUM(A13,2) -> 18
A14: 43963 | B14: Кемерово | C14: 28219.5 | D14: 2595778.5 | E14: =SUMIFS(Лист2!$C:$C,Лист2!$A:$A,A14,Лист2!$B:$B,B14) -> 21 | F14: =SUMIFS(Лист2!$D:$D,Лист2!$A:$A,A14,Лист2!$B:$B,B14) -> 1656 | G14: =SUMIFS(Лист2!$E:$E,Лист2!$A:$A,A14,Лист2!$B:$B,B14) -> 1516 | H14: =D14/E14 -> 123608.5 | I14: =WEEKNUM(A14,2) -> 20
A15: 43972 | B15: Кемерово | C15: 31272 | D15: 2744382 | E15: =SUMIFS(Лист2!$C:$C,Лист2!$A:$A,A15,Лист2!$B:$B,B15) -> 21 | F15: =SUMIFS(Лист2!$D:$D,Лист2!$A:$A,A15,Лист2!$B:$B,B15) -> 1787 | G15: =SUMIFS(Лист2!$E:$E,Лист2!$A:$A,A15,Лист2!$B:$B,B15) -> 1626 | H15: =D15/E15 -> 130684.86 | I15: =WEEKNUM(A15,2) -> 21
A16: 43971 | B16: Кемерово | C16: 34077 | D16: 2929330.5 | E16: =SUMIFS(Лист2!$C:$C,Лист2!$A:$A,A16,Лист2!$B:$B,B16) -> 21 | F16: =SUMIFS(Лист2!$D:$D,Лист2!$A:$A,A16,Лист2!$B:$B,B16) -> 1921 | G16: =SUMIFS(Лист2!$E:$E,Лист2!$A:$A,A16,Лист2!$B:$B,B16) -> 1767 | H16: =D16/E16 -> 139491.93 | I16: =WEEKNUM(A16,2) -> 21
A17: 43956 | B17: Кемерово | C17: 31566 | D17: 2906763 | E17: =SUMIFS(Лист2!$C:$C,Лист2!$A:$A,A17,Лист2!$B:$B,B17) -> 20 | F17: =SUMIFS(Лист2!$D:$D,Лист2!$A:$A,A17,Лист2!$B:$B,B17) -> 1773 | G17: =SUMIFS(Лист2!$E:$E,Лист2!$A:$A,A17,Лист2!$B:$B,B17) -> 1604 | H17: =D17/E17 -> 145338.15 | I17: =WEEKNUM(A17,2) -> 19
A18: 43949 | B18: Кемерово | C18: 26940 | D18: 2411587.5 | E18: =SUMIFS(Лист2!$C:$C,Лист2!$A:$A,A18,Лист2!$B:$B,B18) -> 18 | F18: =SUMIFS(Лист2!$D:$D,Лист2!$A:$A,A18,Лист2!$B:$B,B18) -> 1539 | G18: =SUMIFS(Лист2!$E:$E,Лист2!$A:$A,A18,Лист2!$B:$B,B18) -> 1404 | H18: =D18/E18 -> 133977.08 | I18: =WEEKNUM(A18,2) -> 18
A19: 43964 | B19: Кемерово | C19: 29241 | D19: 2629782 | E19: =SUMIFS(Лист2!$C:$C,Лист2!$A:$A,A19,Лист2!$B:$B,B19) -> 21 | F19: =SUMIFS(Лист2!$D:$D,Лист2!$A:$A,A19,Лист2!$B:$B,B19) -> 1698 | G19: =SUMIFS(Лист2!$E:$E,Лист2!$A:$A,A19,Лист2!$B:$B,B19) -> 1554 | H19: =D19/E19 -> 125227.71 | I19: =WEEKNUM(A19,2) -> 20
A20: 43954 | B20: Кемерово | C20: 26082 | D20: 2434914 | E20: =SUMIFS(Лист2!$C:$C,Лист2!$A:$A,A20,Лист2!$B:$B,B20) -> 20 | F20: =SUMIFS(Лист2!$D:$D,Лист2!$A:$A,A20,Лист2!$B:$B,B20) -> 1520 | G20: =SUMIFS(Лист2!$E:$E,Лист2!$A:$A,A20,Лист2!$B:$B,B20) -> 1373 | H20: =D20/E20 -> 121745.7 | I20: =WEEKNUM(A20,2) -> 18
A21: 43957 | B21: Кемерово | C21: 32511 | D21: 2938623 | E21: =SUMIFS(Лист2!$C:$C,Лист2!$A:$A,A21,Лист2!$B:$B,B21) -> 20 | F21: =SUMIFS(Лист2!$D:$D,Лист2!$A:$A,A21,Лист2!$B:$B,B21) -> 1784 | G21: =SUMIFS(Лист2!$E:$E,Лист2!$A:$A,A21,Лист2!$B:$B,B21) -> 1632 | H21: =D21/E21 -> 146931.15 | I21: =WEEKNUM(A21,2) -> 19
A22: 43974 | B22: Кемерово | C22: 42703.5 | D22: 3628726.5 | E22: =SUMIFS(Лист2!$C:$C,Лист2!$A:$A,A22,Лист2!$B:$B,B22) -> 21 | F22: =SUMIFS(Лист2!$D:$D,Лист2!$A:$A,A22,Лист2!$B:$B,B22) -> 2340 | G22: =SUMIFS(Лист2!$E:$E,Лист2!$A:$A,A22,Лист2!$B:$B,B22) -> 2146 | H22: =D22/E22 -> 172796.5 | I22: =WEEKNUM(A22,2) -> 21
A23: 43976 | B23: Кемерово | C23: 35592 | D23: 3176580 | E23: =SUMIFS(Лист2!$C:$C,Лист2!$A:$A,A23,Лист2!$B:$B,B23) -> 20 | F23: =SUMIFS(Лист2!$D:$D,Лист2!$A:$A,A23,Лист2!$B:$B,B23) -> 2087 | G23: =SUMIFS(Лист2!$E:$E,Лист2!$A:$A,A23,Лист2!$B:$B,B23) -> 1914 | H23: =D23/E23 -> 158829 | I23: =WEEKNUM(A23,2) -> 22 | T23: Территория | U23: Товарооборот, руб | V23: Товарооборот на склад
A24: 43951 | B24: Кемерово | C24: 30445.5 | D24: 2817196.5 | E24: =SUMIFS(Лист2!$C:$C,Лист2!$A:$A,A24,Лист2!$B:$B,B24) -> 19 | F24: =SUMIFS(Лист2!$D:$D,Лист2!$A:$A,A24,Лист2!$B:$B,B24) -> 1712 | G24: =SUMIFS(Лист2!$E:$E,Лист2!$A:$A,A24,Лист2!$B:$B,B24) -> 1552 | H24: =D24/E24 -> 148273.5 | I24: =WEEKNUM(A24,2) -> 18 | T24: 18 | U24: 836803032 | V24: 249494.05
A25: 43961 | B25: Кемерово | C25: 36619.5 | D25: 3312967.5 | E25: =SUMIFS(Лист2!$C:$C,Лист2!$A:$A,A25,Лист2!$B:$B,B25) -> 21 | F25: =SUMIFS(Лист2!$D:$D,Лист2!$A:$A,A25,Лист2!$B:$B,B25) -> 2016 | G25: =SUMIFS(Лист2!$E:$E,Лист2!$A:$A,A25,Лист2!$B:$B,B25) -> 1846 | H25: =D25/E25 -> 157760.36 | I25: =WEEKNUM(A25,2) -> 19 | T25: 19 | U25: 9.8391541e+08 | V25: 247401.41
A26: 43959 | B26: Кемерово | C26: 29409 | D26: 2645160 | E26: =SUMIFS(Лист2!$C:$C,Лист2!$A:$A,A26,Лист2!$B:$B,B26) -> 21 | F26: =SUMIFS(Лист2!$D:$D,Лист2!$A:$A,A26,Лист2!$B:$B,B26) -> 1646 | G26: =SUMIFS(Лист2!$E:$E,Лист2!$A:$A,A26,Лист2!$B:$B,B26) -> 1492 | H26: =D26/E26 -> 125960 | I26: =WEEKNUM(A26,2) -> 19 | T26: 20 | U26: 9.4726301e+08 | V26: 237171.51
A27: 43958 | B27: Кемерово | C27: 27018 | D27: 2472213 | E27: =SUMIFS(Лист2!$C:$C,Лист2!$A:$A,A27,Лист2!$B:$B,B27) -> 21 | F27: =SUMIFS(Лист2!$D:$D,Лист2!$A:$A,A27,Лист2!$B:$B,B27) -> 1542 | G27: =SUMIFS(Лист2!$E:$E,Лист2!$A:$A,A27,Лист2!$B:$B,B27) -> 1405 | H27: =D27/E27 -> 117724.43 | I27: =WEEKNUM(A27,2) -> 19 | T27: 21 | U27: 1.0026919e+09 | V27: 249425.84
A28: 43975 | B28: Кемерово | C28: 34303.5 | D28: 2924746.5 | E28: =SUMIFS(Лист2!$C:$C,Лист2!$A:$A,A28,Лист2!$B:$B,B28) -> 20 | F28: =SUMIFS(Лист2!$D:$D,Лист2!$A:$A,A28,Лист2!$B:$B,B28) -> 1999 | G28: =SUMIFS(Лист2!$E:$E,Лист2!$A:$A,A28,Лист2!$B:$B,B28) -> 1829 | H28: =D28/E28 -> 146237.33 | I28: =WEEKNUM(A28,2) -> 21 | T28: 22 | U28: 1.0556535e+09 | V28: 254313.06
A29: 43982 | B29: Кемерово | C29: 36999 | D29: 3473895 | E29: =SUMIFS(Лист2!$C:$C,Лист2!$A:$A,A29,Лист2!$B:$B,B29) -> 21 | F29: =SUMIFS(Лист2!$D:$D,Лист2!$A:$A,A29,Лист2!$B:$B,B29) -> 2271 | G29: =SUMIFS(Лист2!$E:$E,Лист2!$A:$A,A29,Лист2!$B:$B,B29) -> 2085 | H29: =D29/E29 -> 165423.57 | I29: =WEEKNUM(A29,2) -> 22 | T29: 23 | U29: 1.3603238e+08 | V29: 221190.86
A30: 43981 | B30: Кемерово | C30: 44001 | D30: 3921784.5 | E30: =SUMIFS(Лист2!$C:$C,Лист2!$A:$A,A30,Лист2!$B:$B,B30) -> 20 | F30: =SUMIFS(Лист2!$D:$D,Лист2!$A:$A,A30,Лист2!$B:$B,B30) -> 2597 | G30: =SUMIFS(Лист2!$E:$E,Лист2!$A:$A,A30,Лист2!$B:$B,B30) -> 2376 | H30: =D30/E30 -> 196089.23 | I30: =WEEKNUM(A30,2) -> 22 | T30: Общий итог | U30: 4.9623592e+09 | V30: 246748.51
A31: 43979 | B31: Кемерово | C31: 30982.5 | D31: 2827773 | E31: =SUMIFS(Лист2!$C:$C,Лист2!$A:$A,A31,Лист2!$B:$B,B31) -> 20 | F31: =SUMIFS(Лист2!$D:$D,Лист2!$A:$A,A31,Лист2!$B:$B,B31) -> 1886 | G31: =SUMIFS(Лист2!$E:$E,Лист2!$A:$A,A31,Лист2!$B:$B,B31) -> 1736 | H31: =D31/E31 -> 141388.65 | I31: =WEEKNUM(A31,2) -> 22
A32: 43967 | B32: Екатеринбург | C32: 88063.5 | D32: 7583758.5 | E32: =SUMIFS(Лист2!$C:$C,Лист2!$A:$A,A32,Лист2!$B:$B,B32) -> 31 | F32: =SUMIFS(Лист2!$D:$D,Лист2!$A:$A,A32,Лист2!$B:$B,B32) -> 5593 | G32: =SUMIFS(Лист2!$E:$E,Лист2!$A:$A,A32,Лист2!$B:$B,B32) -> 5177 | H32: =D32/E32 -> 244637.37 | I32: =WEEKNUM(A32,2) -> 20
A33: 43970 | B33: Екатеринбург | C33: 84024 | D33: 6815511 | E33: =SUMIFS(Лист2!$C:$C,Лист2!$A:$A,A33,Лист2!$B:$B,B33) -> 31 | F33: =SUMIFS(Лист2!$D:$D,Лист2!$A:$A,A33,Лист2!$B:$B,B33) -> 5389 | G33: =SUMIFS(Лист2!$E:$E,Лист2!$A:$A,A33,Лист2!$B:$B,B33) -> 5024 | H33: =D33/E33 -> 219855.19 | I33: =WEEKNUM(A33,2) -> 21
A34: 43968 | B34: Екатеринбург | C34: 78057 | D34: 6774946.5 | E34: =SUMIFS(Лист2!$C:$C,Лист2!$A:$A,A34,Лист2!$B:$B,B34) -> 31 | F34: =SUMIFS(Лист2!$D:$D,Лист2!$A:$A,A34,Лист2!$B:$B,B34) -> 5206 | G34: =SUMIFS(Лист2!$E:$E,Лист2!$A:$A,A34,Лист2!$B:$B,B34) -> 4843 | H34: =D34/E34 -> 218546.66 | I34: =WEEKNUM(A34,2) -> 20
A35: 43960 | B35: Екатеринбург | C35: 69720 | D35: 6264933 | E35: =SUMIFS(Лист2!$C:$C,Лист2!$A:$A,A35,Лист2!$B:$B,B35) -> 31 | F35: =SUMIFS(Лист2!$D:$D,Лист2!$A:$A,A35,Лист2!$B:$B,B35) -> 4556 | G35: =SUMIFS(Лист2!$E:$E,Лист2!$A:$A,A35,Лист2!$B:$B,B35) -> 4220 | H35: =D35/E35 -> 202094.61 | I35: =WEEKNUM(A35,2) -> 19
A36: 43955 | B36: Екатеринбург | C36: 72928.5 | D36: 6642249 | E36: =SUMIFS(Лист2!$C:$C,Лист2!$A:$A,A36,Лист2!$B:$B,B36) -> 31 | F36: =SUMIFS(Лист2!$D:$D,Лист2!$A:$A,A36,Лист2!$B:$B,B36) -> 4968 | G36: =SUMIFS(Лист2!$E:$E,Лист2!$A:$A,A36,Лист2!$B:$B,B36) -> 4596 | H36: =D36/E36 -> 214266.1 | I36: =WEEKNUM(A36,2) -> 19
A37: 43950 | B37: Екатеринбург | C37: 79527 | D37: 7180498.5 | E37: =SUMIFS(Лист2!$C:$C,Лист2!$A:$A,A37,Лист2!$B:$B,B37) -> 31 | F37: =SUMIFS(Лист2!$D:$D,Лист2!$A:$A,A37,Лист2!$B:$B,B37) -> 5378 | G37: =SUMIFS(Лист2!$E:$E,Лист2!$A:$A,A37,Лист2!$B:$B,B37) -> 4985 | H37: =D37/E37 -> 231628.98 | I37: =WEEKNUM(A37,2) -> 18
A38: 43953 | B38: Екатеринбург | C38: 60463.5 | D38: 5554192.5 | E38: =SUMIFS(Лист2!$C:$C,Лист2!$A:$A,A38,Лист2!$B:$B,B38) -> 31 | F38: =SUMIFS(Лист2!$D:$D,Лист2!$A:$A,A38,Лист2!$B:$B,B38) -> 4157 | G38: =SUMIFS(Лист2!$E:$E,Лист2!$A:$A,A38,Лист2!$B:$B,B38) -> 3823 | H38: =D38/E38 -> 179167.5 | I38: =WEEKNUM(A38,2) -> 18
A39: 43977 | B39: Екатеринбург | C39: 79975.5 | D39: 6676459.5 | E39: =SUMIFS(Лист2!$C:$C,Лист2!$A:$A,A39,Лист2!$B:$B,B39) -> 31 | F39: =SUMIFS(Лист2!$D:$D,Лист2!$A:$A,A39,Лист2!$B:$B,B39) -> 5493 | G39: =SUMIFS(Лист2!$E:$E,Лист2!$A:$A,A39,Лист2!$B:$B,B39) -> 5119 | H39: =D39/E39 -> 215369.66 | I39: =WEEKNUM(A39,2) -> 22
A40: 43952 | B40: Екатеринбург | C40: 97534.5 | D40: 8893024.5 | E40: =SUMIFS(Лист2!$C:$C,Лист2!$A:$A,A40,Лист2!$B:$B,B40) -> 31 | F40: =SUMIFS(Лист2!$D:$D,Лист2!$A:$A,A40,Лист2!$B:$B,B40) -> 6118 | G40: =SUMIFS(Лист2!$E:$E,Лист2!$A:$A,A40,Лист2!$B:$B,B40) -> 5564 | H40: =D40/E40 -> 286871.76 | I40: =WEEKNUM(A40,2) -> 18
...

Sheet Лист2
A1: Дата | B1: Территория | C1: Количество складов | D1: Количество заказов | E1: Количество клиентов
A2: 43949 | B2: Волгоград | C2: 36 | D2: 4923 | E2: 4560
A3: 43949 | B3: Екатеринбург | C3: 31 | D3: 5465 | E3: 5096
A4: 43949 | B4: Казань | C4: 19 | D4: 1846 | E4: 1681
A5: 43949 | B5: Кемерово | C5: 18 | D5: 1539 | E5: 1404
A6: 43949 | B6: Краснодар | C6: 18 | D6: 1505 | E6: 1368
A7: 43949 | B7: Москва Восток | C7: 54 | D7: 12306 | E7: 11532
A8: 43949 | B8: Москва Запад | C8: 59 | D8: 12943 | E8: 12072
A9: 43949 | B9: Нижний Новгород | C9: 17 | D9: 1439 | E9: 1265
A10: 43949 | B10: Новосибирск | C10: 15 | D10: 636 | E10: 547
A11: 43949 | B11: Пермь | C11: 15 | D11: 780 | E11: 690
A12: 43949 | B12: Санкт-Петербург Север | C12: 125 | D12: 20914 | E12: 19479
A13: 43949 | B13: Санкт-Петербург Юг | C13: 128 | D13: 16450 | E13: 15320
... A505: 43983 | B505: Уфа | C505: 6 | D505: 237 | E505: 175
